---
title: Příkaz throw nemůže vynechat operand vně příkazu catch nebo uvnitř příkazu finally.
ms.date: 07/20/2015
f1_keywords:
- vbc30666
- bc30666
helpviewer_keywords:
- BC30666
ms.assetid: a208a6ea-0e36-4bf1-8984-4de1a0e38a2a
ms.openlocfilehash: c4ab115b01e78c245cbd9f564b50573d6e30c5e7
ms.sourcegitcommit: f8c270376ed905f6a8896ce0fe25b4f4b38ff498
ms.translationtype: MT
ms.contentlocale: cs-CZ
ms.lasthandoff: 06/04/2020
ms.locfileid: "84414930"
---
# <a name="throw-statement-cannot-omit-operand-outside-a-catch-statement-or-inside-a-finally-statement"></a>Příkaz throw nemůže vynechat operand vně příkazu catch nebo uvnitř příkazu finally.
`Throw`příkazy mimo `Catch` příkaz musí poskytovat název objektu výjimky.  
  
 **ID chyby:** BC30666  
  
## <a name="to-correct-this-error"></a>Oprava této chyby  
  
1. Zadejte název objektu výjimky odvozený z `System.Exception` .  
  
2. Restrukturalizujte kód tak, aby byl `Throw` příkaz uvnitř `Catch` bloku.  
  
## <a name="see-also"></a>Viz také

- [Throw – příkaz](../language-reference/statements/throw-statement.md)
- [Try...Catch....Finally – příkaz](../language-reference/statements/try-catch-finally-statement.md)
- <xref:System.Exception?displayProperty=nameWithType>
- [Zpracování a vyvolávání výjimek v rozhraní .NET](../../standard/exceptions/index.md)
