---
title: Zpracování výjimek (Task Parallel Library)
description: Prozkoumejte zpracování výjimek pomocí Task Parallel Library (TPL) v rozhraní .NET. Viz vnořené agregované výjimky, vnitřní výjimky, nepozorované výjimky úloh & další.
ms.date: 04/20/2020
ms.technology: dotnet-standard
dev_langs:
- csharp
- vb
helpviewer_keywords:
- tasks, exceptions
ms.assetid: beb51e50-9061-4d3d-908c-56a4f7c2e8c1
ms.openlocfilehash: f1c1a994f4b3a8df0556a0190bc4eacb63f2921e
ms.sourcegitcommit: 7137e12f54c4e83a94ae43ec320f8cf59c1772ea
ms.translationtype: MT
ms.contentlocale: cs-CZ
ms.lasthandoff: 06/10/2020
ms.locfileid: "84662534"
---
# <a name="exception-handling-task-parallel-library"></a><span data-ttu-id="82357-104">Zpracování výjimek (Task Parallel Library)</span><span class="sxs-lookup"><span data-stu-id="82357-104">Exception handling (Task Parallel Library)</span></span>

<span data-ttu-id="82357-105">Neošetřené výjimky, které jsou vyvolány uživatelským kódem, který je spuštěn v rámci úlohy, jsou šířeny zpět do volajícího vlákna, s výjimkou některých scénářů, které jsou popsány dále v tomto tématu.</span><span class="sxs-lookup"><span data-stu-id="82357-105">Unhandled exceptions that are thrown by user code that is running inside a task are propagated back to the calling thread, except in certain scenarios that are described later in this topic.</span></span> <span data-ttu-id="82357-106">Výjimky jsou šířeny při použití jedné ze statických nebo instančních <xref:System.Threading.Tasks.Task.Wait%2A?displayProperty=nameWithType> metod a jejich zpracování uzavřením volání do `try` / `catch` příkazu.</span><span class="sxs-lookup"><span data-stu-id="82357-106">Exceptions are propagated when you use one of the static or instance <xref:System.Threading.Tasks.Task.Wait%2A?displayProperty=nameWithType> methods, and you handle them by enclosing the call in a `try`/`catch` statement.</span></span> <span data-ttu-id="82357-107">Pokud je úkol nadřazený k připojeným podřízeným úkolům nebo pokud čekáte na více úloh, může být vyvoláno více výjimek.</span><span class="sxs-lookup"><span data-stu-id="82357-107">If a task is the parent of attached child tasks, or if you are waiting on multiple tasks, multiple exceptions could be thrown.</span></span>

<span data-ttu-id="82357-108">Aby bylo možné šířit všechny výjimky zpět do hlavního vlákna, infrastruktura úkolů je zabaluje do instance <xref:System.AggregateException>.</span><span class="sxs-lookup"><span data-stu-id="82357-108">To propagate all the exceptions back to the calling thread, the Task infrastructure wraps them in an <xref:System.AggregateException> instance.</span></span> <span data-ttu-id="82357-109"><xref:System.AggregateException>Výjimka má <xref:System.AggregateException.InnerExceptions%2A> vlastnost, která může být vytvořena výčtem, aby prověřila všechny původní výjimky, které byly vyvolány, a zpracovala (nebo nezpracovává) každou z nich jednotlivě.</span><span class="sxs-lookup"><span data-stu-id="82357-109">The <xref:System.AggregateException> exception has an <xref:System.AggregateException.InnerExceptions%2A> property that can be enumerated to examine all the original exceptions that were thrown, and handle (or not handle) each one individually.</span></span> <span data-ttu-id="82357-110">Původní výjimky lze také zpracovat pomocí <xref:System.AggregateException.Handle%2A?displayProperty=nameWithType> metody.</span><span class="sxs-lookup"><span data-stu-id="82357-110">You can also handle the original exceptions by using the <xref:System.AggregateException.Handle%2A?displayProperty=nameWithType> method.</span></span>

<span data-ttu-id="82357-111">I v případě, že je vyvolána pouze jedna výjimka, je stále zabalena do <xref:System.AggregateException> výjimky, jak ukazuje následující příklad.</span><span class="sxs-lookup"><span data-stu-id="82357-111">Even if only one exception is thrown, it is still wrapped in an <xref:System.AggregateException> exception, as the following example shows.</span></span>

[!code-csharp[TPL_Exceptions#21](../../../samples/snippets/csharp/VS_Snippets_Misc/tpl_exceptions/cs/handling21.cs#21)]
[!code-vb[TPL_Exceptions#21](../../../samples/snippets/visualbasic/VS_Snippets_Misc/tpl_exceptions/vb/handling21.vb#21)]

<span data-ttu-id="82357-112">Nezpracované výjimce se můžete vyhnout zachycením instance <xref:System.AggregateException> a ignorováním jakýchkoli vnitřních výjimek.</span><span class="sxs-lookup"><span data-stu-id="82357-112">You could avoid an unhandled exception by just catching the <xref:System.AggregateException> and not observing any of the inner exceptions.</span></span> <span data-ttu-id="82357-113">Nicméně doporučujeme, abyste to provedli, protože se podobá zachycení základního <xref:System.Exception> typu v neparalelních scénářích.</span><span class="sxs-lookup"><span data-stu-id="82357-113">However, we recommend that you do not do this because it is analogous to catching the base <xref:System.Exception> type in non-parallel scenarios.</span></span> <span data-ttu-id="82357-114">Pokud zachytíte výjimku, a potom neprovedete žádnou konkrétní akci zotavení, bude program ponechán v neurčitém stavu.</span><span class="sxs-lookup"><span data-stu-id="82357-114">To catch an exception without taking specific actions to recover from it can leave your program in an indeterminate state.</span></span>

<span data-ttu-id="82357-115">Pokud nechcete volat <xref:System.Threading.Tasks.Task.Wait%2A?displayProperty=nameWithType> metodu pro čekání na dokončení úlohy, můžete také načíst <xref:System.AggregateException> výjimku z <xref:System.Threading.Tasks.Task.Exception%2A> vlastnosti úkolu, jak ukazuje následující příklad.</span><span class="sxs-lookup"><span data-stu-id="82357-115">If you do not want to call the <xref:System.Threading.Tasks.Task.Wait%2A?displayProperty=nameWithType> method to wait for a task's completion, you can also retrieve the <xref:System.AggregateException> exception from the task's <xref:System.Threading.Tasks.Task.Exception%2A> property, as the following example shows.</span></span> <span data-ttu-id="82357-116">Další informace naleznete v části [sledování výjimek pomocí vlastnosti Task. Exception](#observing-exceptions-by-using-the-taskexception-property) v tomto tématu.</span><span class="sxs-lookup"><span data-stu-id="82357-116">For more information, see the [Observing exceptions by using the Task.Exception property](#observing-exceptions-by-using-the-taskexception-property) section in this topic.</span></span>

[!code-csharp[TPL_Exceptions#29](../../../samples/snippets/csharp/VS_Snippets_Misc/tpl_exceptions/cs/handling22.cs#29)]
[!code-vb[TPL_Exceptions#29](../../../samples/snippets/visualbasic/VS_Snippets_Misc/tpl_exceptions/vb/handling22.vb#29)]

<span data-ttu-id="82357-117">Pokud nečekáte na úlohu, která šíří výjimku, nebo ke své <xref:System.Threading.Tasks.Task.Exception%2A> vlastnosti, je výjimka předávána v souladu se zásadami výjimky rozhraní .NET, pokud je úloha uvolněna z paměti.</span><span class="sxs-lookup"><span data-stu-id="82357-117">If you do not wait on a task that propagates an exception, or access its <xref:System.Threading.Tasks.Task.Exception%2A> property, the exception is escalated according to the .NET exception policy when the task is garbage-collected.</span></span>

<span data-ttu-id="82357-118">Pokud jsou výjimky povoleny k bublinám zpět do spojovacího vlákna, je možné, že úloha může pokračovat ve zpracování některých položek poté, co je vyvolána výjimka.</span><span class="sxs-lookup"><span data-stu-id="82357-118">When exceptions are allowed to bubble up back to the joining thread, it is possible that a task may continue to process some items after the exception is raised.</span></span>

> [!NOTE]
> <span data-ttu-id="82357-119">Pokud je povolena vlastnost „Pouze vlastní kód“, zastaví se sada Visual Studio v některých případech na řádce, která výjimku vyvolá, a zobrazí chybovou zprávu s upozorněním, že „výjimka není zpracována uživatelským kódem“.</span><span class="sxs-lookup"><span data-stu-id="82357-119">When "Just My Code" is enabled, Visual Studio in some cases will break on the line that throws the exception and display an error message that says "exception not handled by user code."</span></span> <span data-ttu-id="82357-120">Tato chyba je neškodná.</span><span class="sxs-lookup"><span data-stu-id="82357-120">This error is benign.</span></span> <span data-ttu-id="82357-121">Můžete pokračovat stisknutím klávesy F5 a zjistit, jakým způsobem jsou zpracovaný výjimky, což je znázorněno v těchto příkladech.</span><span class="sxs-lookup"><span data-stu-id="82357-121">You can press F5 to continue and see the exception-handling behavior that is demonstrated in these examples.</span></span> <span data-ttu-id="82357-122">Chcete-li aplikaci Visual Studio zabránit v přerušení první chyby, zrušte zaškrtnutí políčka **povolit pouze můj kód** v části **nástroje, možnosti, ladění, obecné**.</span><span class="sxs-lookup"><span data-stu-id="82357-122">To prevent Visual Studio from breaking on the first error, just uncheck the **Enable Just My Code** checkbox under **Tools, Options, Debugging, General**.</span></span>

## <a name="attached-child-tasks-and-nested-aggregateexceptions"></a><span data-ttu-id="82357-123">Připojené podřízené úlohy a vnořené AggregateExceptions</span><span class="sxs-lookup"><span data-stu-id="82357-123">Attached child tasks and nested AggregateExceptions</span></span>

<span data-ttu-id="82357-124">Pokud úloha obsahuje připojené podřízené úlohy, které způsobí výjimku, je tato výjimka zabalená do instance <xref:System.AggregateException> předtím, než je postoupena do nadřazené úlohy, která zabalí tuto výjimku do vlastní instance <xref:System.AggregateException> dříve, než ji postoupí zpět do volajícího vlákna.</span><span class="sxs-lookup"><span data-stu-id="82357-124">If a task has an attached child task that throws an exception, that exception is wrapped in an <xref:System.AggregateException> before it is propagated to the parent task, which wraps that exception in its own <xref:System.AggregateException> before it propagates it back to the calling thread.</span></span> <span data-ttu-id="82357-125">V takových případech <xref:System.AggregateException.InnerExceptions%2A> vlastnost <xref:System.AggregateException> výjimky, která je zachycena v <xref:System.Threading.Tasks.Task.Wait%2A?displayProperty=nameWithType> <xref:System.Threading.Tasks.Task.WaitAny%2A> metodě, nebo <xref:System.Threading.Tasks.Task.WaitAll%2A> obsahuje jednu nebo více <xref:System.AggregateException> instancí, nikoli původní výjimky, které způsobily chybu.</span><span class="sxs-lookup"><span data-stu-id="82357-125">In such cases, the <xref:System.AggregateException.InnerExceptions%2A> property of the <xref:System.AggregateException> exception that is caught at the <xref:System.Threading.Tasks.Task.Wait%2A?displayProperty=nameWithType>, <xref:System.Threading.Tasks.Task.WaitAny%2A>, or <xref:System.Threading.Tasks.Task.WaitAll%2A> method contains one or more <xref:System.AggregateException> instances, not the original exceptions that caused the fault.</span></span> <span data-ttu-id="82357-126">Chcete-li se vyhnout nutnosti iterovat vnořené <xref:System.AggregateException> výjimky, můžete použít <xref:System.AggregateException.Flatten%2A> metodu k odebrání všech vnořených <xref:System.AggregateException> výjimek, takže <xref:System.AggregateException.InnerExceptions%2A?displayProperty=nameWithType> vlastnost obsahuje původní výjimky.</span><span class="sxs-lookup"><span data-stu-id="82357-126">To avoid having to iterate over nested <xref:System.AggregateException> exceptions, you can use the <xref:System.AggregateException.Flatten%2A> method to remove all the nested <xref:System.AggregateException> exceptions, so that the <xref:System.AggregateException.InnerExceptions%2A?displayProperty=nameWithType> property contains the original exceptions.</span></span> <span data-ttu-id="82357-127">V následujícím příkladu jsou vnořené instance <xref:System.AggregateException> zploštěny a zpracovávány pouze v jednom průchodu.</span><span class="sxs-lookup"><span data-stu-id="82357-127">In the following example, nested <xref:System.AggregateException> instances are flattened and handled in just one loop.</span></span>

[!code-csharp[TPL_Exceptions#22](../../../samples/snippets/csharp/VS_Snippets_Misc/tpl_exceptions/cs/flatten2.cs#22)]
[!code-vb[TPL_Exceptions#22](../../../samples/snippets/visualbasic/VS_Snippets_Misc/tpl_exceptions/vb/flatten2.vb#22)]

<span data-ttu-id="82357-128">Můžete také použít <xref:System.AggregateException.Flatten%2A?displayProperty=nameWithType> metodu k opětovnému vyvolání vnitřních výjimek z více <xref:System.AggregateException> instancí vyvolaných více úlohami v rámci jedné <xref:System.AggregateException> instance, jak ukazuje následující příklad.</span><span class="sxs-lookup"><span data-stu-id="82357-128">You can also use the <xref:System.AggregateException.Flatten%2A?displayProperty=nameWithType> method to rethrow the inner exceptions from multiple <xref:System.AggregateException> instances thrown by multiple tasks in a single <xref:System.AggregateException> instance, as the following example shows.</span></span>

[!code-csharp[TPL_Exceptions#13](../../../samples/snippets/csharp/VS_Snippets_Misc/tpl_exceptions/cs/taskexceptions2.cs#13)]
[!code-vb[TPL_Exceptions#13](../../../samples/snippets/visualbasic/VS_Snippets_Misc/tpl_exceptions/vb/taskexceptions2.vb#13)]

## <a name="exceptions-from-detached-child-tasks"></a><span data-ttu-id="82357-129">Výjimky z odpojených podřízených úloh</span><span class="sxs-lookup"><span data-stu-id="82357-129">Exceptions from detached child tasks</span></span>

<span data-ttu-id="82357-130">Ve výchozím nastavení jsou podřízené úkoly vytvořeny jako odpojené.</span><span class="sxs-lookup"><span data-stu-id="82357-130">By default, child tasks are created as detached.</span></span> <span data-ttu-id="82357-131">Výjimky vyvolané z odpojených úkolů musí být zpracovány nebo znovu vyvolány ihned v nadřazeném úkolu. Tyto výjimky nejsou šířeny zpět do volajícího vlákna stejným způsobem jako připojené úkoly.</span><span class="sxs-lookup"><span data-stu-id="82357-131">Exceptions thrown from detached tasks must be handled or rethrown in the immediate parent task; they are not propagated back to the calling thread in the same way as attached child tasks propagated back.</span></span> <span data-ttu-id="82357-132">Nejvyšší nadřazený prvek může ručně znovu vyvolat výjimku z odpojeného podřízeného objektu, aby mohl být zabalen do <xref:System.AggregateException> a šířen zpět do volajícího vlákna.</span><span class="sxs-lookup"><span data-stu-id="82357-132">The topmost parent can manually rethrow an exception from a detached child to cause it to be wrapped in an <xref:System.AggregateException> and propagated back to the calling thread.</span></span>

[!code-csharp[TPL_Exceptions#23](../../../samples/snippets/csharp/VS_Snippets_Misc/tpl_exceptions/cs/detached21.cs#23)]
[!code-vb[TPL_Exceptions#23](../../../samples/snippets/visualbasic/VS_Snippets_Misc/tpl_exceptions/vb/detached21.vb#23)]

<span data-ttu-id="82357-133">I pokud používáte pokračování pro sledování výjimky v podřízeném úkolu, musí být výjimka stále sledována nadřazeným úkolem.</span><span class="sxs-lookup"><span data-stu-id="82357-133">Even if you use a continuation to observe an exception in a child task, the exception still must be observed by the parent task.</span></span>

## <a name="exceptions-that-indicate-cooperative-cancellation"></a><span data-ttu-id="82357-134">Výjimky indikující kooperativní zrušení</span><span class="sxs-lookup"><span data-stu-id="82357-134">Exceptions that indicate cooperative cancellation</span></span>

<span data-ttu-id="82357-135">Pokud uživatelský kód v rámci úkolu odpoví na požadavek zrušení, mělo by správně dojít k vyvolání výjimky <xref:System.OperationCanceledException> a předání v tokenu zrušení, na kterém byl požadavek sdělen.</span><span class="sxs-lookup"><span data-stu-id="82357-135">When user code in a task responds to a cancellation request, the correct procedure is to throw an <xref:System.OperationCanceledException> passing in the cancellation token on which the request was communicated.</span></span> <span data-ttu-id="82357-136">Dříve než se pokusí o postoupení výjimky, porovná úkol token ve výjimce s tokenem, který byl předán při vytváření.</span><span class="sxs-lookup"><span data-stu-id="82357-136">Before it attempts to propagate the exception, the task instance compares the token in the exception to the one that was passed to it when it was created.</span></span> <span data-ttu-id="82357-137">Pokud se shodují, daný úkol postoupí výjimku <xref:System.Threading.Tasks.TaskCanceledException> zabalenou v instanci <xref:System.AggregateException> a lze ji zobrazit při ověřování vnořené výjimky.</span><span class="sxs-lookup"><span data-stu-id="82357-137">If they are the same, the task propagates a <xref:System.Threading.Tasks.TaskCanceledException> wrapped in the <xref:System.AggregateException>, and it can be seen when the inner exceptions are examined.</span></span> <span data-ttu-id="82357-138">Nicméně pokud volající vlákno nečeká na úlohu, tato specifická výjimka nebude šířena.</span><span class="sxs-lookup"><span data-stu-id="82357-138">However, if the calling thread is not waiting on the task, this specific exception will not be propagated.</span></span> <span data-ttu-id="82357-139">Další informace najdete v tématu [zrušení úlohy](task-cancellation.md).</span><span class="sxs-lookup"><span data-stu-id="82357-139">For more information, see [Task Cancellation](task-cancellation.md).</span></span>

[!code-csharp[TPL_Exceptions#4](../../../samples/snippets/csharp/VS_Snippets_Misc/tpl_exceptions/cs/exceptions.cs#4)]
[!code-vb[TPL_Exceptions#4](../../../samples/snippets/visualbasic/VS_Snippets_Misc/tpl_exceptions/vb/tpl_exceptions.vb#4)]

## <a name="using-the-handle-method-to-filter-inner-exceptions"></a><span data-ttu-id="82357-140">Použití metody Handle k filtrování vnitřních výjimek</span><span class="sxs-lookup"><span data-stu-id="82357-140">Using the handle method to filter inner exceptions</span></span>

<span data-ttu-id="82357-141">Metodu <xref:System.AggregateException.Handle%2A?displayProperty=nameWithType> můžete použít k filtrování výjimek, které lze považovat jako „zpracované“ bez použití jakékoli další logiky.</span><span class="sxs-lookup"><span data-stu-id="82357-141">You can use the <xref:System.AggregateException.Handle%2A?displayProperty=nameWithType> method to filter out exceptions that you can treat as "handled" without using any further logic.</span></span> <span data-ttu-id="82357-142">V uživatelském delegátu, který je dodán <xref:System.AggregateException.Handle%28System.Func%7BSystem.Exception%2CSystem.Boolean%7D%29?displayProperty=nameWithType> metodě, můžete prověřit typ výjimky, jeho <xref:System.Exception.Message%2A> vlastnost nebo jakékoli jiné informace, které vám umožní určit, zda je neškodný.</span><span class="sxs-lookup"><span data-stu-id="82357-142">In the user delegate that is supplied to the <xref:System.AggregateException.Handle%28System.Func%7BSystem.Exception%2CSystem.Boolean%7D%29?displayProperty=nameWithType> method, you can examine the exception type, its <xref:System.Exception.Message%2A> property, or any other information about it that will let you determine whether it is benign.</span></span> <span data-ttu-id="82357-143">Jakékoli výjimky, pro které se delegát vrátí, `false` se znovu vyvolají v nové <xref:System.AggregateException> instanci hned po <xref:System.AggregateException.Handle%2A?displayProperty=nameWithType> návratu metody.</span><span class="sxs-lookup"><span data-stu-id="82357-143">Any exceptions for which the delegate returns `false` are rethrown in a new <xref:System.AggregateException> instance immediately after the <xref:System.AggregateException.Handle%2A?displayProperty=nameWithType> method returns.</span></span>

<span data-ttu-id="82357-144">Následující příklad je funkčně ekvivalentní k prvnímu příkladu v tomto tématu, který prověřuje každou výjimku v <xref:System.AggregateException.InnerExceptions%2A?displayProperty=nameWithType> kolekci.</span><span class="sxs-lookup"><span data-stu-id="82357-144">The following example is functionally equivalent to the first example in this topic, which examines each exception in the <xref:System.AggregateException.InnerExceptions%2A?displayProperty=nameWithType> collection.</span></span>  <span data-ttu-id="82357-145">Místo toho tato obslužná rutina výjimky volá <xref:System.AggregateException.Handle%2A?displayProperty=nameWithType> objekt metody pro každou výjimku a znovu vyvolá výjimky, které nejsou `CustomException` instancemi.</span><span class="sxs-lookup"><span data-stu-id="82357-145">Instead, this exception handler calls the <xref:System.AggregateException.Handle%2A?displayProperty=nameWithType> method object for each exception, and only rethrows exceptions that are not `CustomException` instances.</span></span>

[!code-csharp[TPL_Exceptions#26](../../../samples/snippets/csharp/VS_Snippets_Misc/tpl_exceptions/cs/handlemethod21.cs#26)]
[!code-vb[TPL_Exceptions#26](../../../samples/snippets/visualbasic/VS_Snippets_Misc/tpl_exceptions/vb/handlemethod21.vb#26)]

<span data-ttu-id="82357-146">Následuje příklad kompletního příkladu, který používá <xref:System.AggregateException.Handle%2A?displayProperty=nameWithType> metodu k poskytnutí speciálního zpracování <xref:System.UnauthorizedAccessException> výjimky při vytváření výčtu souborů.</span><span class="sxs-lookup"><span data-stu-id="82357-146">The following is a more complete example that uses the <xref:System.AggregateException.Handle%2A?displayProperty=nameWithType> method to provide special handling for an <xref:System.UnauthorizedAccessException> exception when enumerating files.</span></span>

[!code-csharp[TPL_Exceptions#12](../../../samples/snippets/csharp/VS_Snippets_Misc/tpl_exceptions/cs/taskexceptions.cs#12)]
[!code-vb[TPL_Exceptions#12](../../../samples/snippets/visualbasic/VS_Snippets_Misc/tpl_exceptions/vb/taskexceptions.vb#12)]

## <a name="observing-exceptions-by-using-the-taskexception-property"></a><span data-ttu-id="82357-147">Pozorování výjimek pomocí vlastnosti Task. Exception</span><span class="sxs-lookup"><span data-stu-id="82357-147">Observing exceptions by using the Task.Exception property</span></span>

<span data-ttu-id="82357-148">Pokud úkol skončí ve stavu <xref:System.Threading.Tasks.TaskStatus.Faulted?displayProperty=nameWithType>, může být její vlastnost <xref:System.Threading.Tasks.Task.Exception%2A> přezkoumána a zjištěna výjimka, která chybu způsobila.</span><span class="sxs-lookup"><span data-stu-id="82357-148">If a task completes in the <xref:System.Threading.Tasks.TaskStatus.Faulted?displayProperty=nameWithType> state, its <xref:System.Threading.Tasks.Task.Exception%2A> property can be examined to discover which specific exception caused the fault.</span></span> <span data-ttu-id="82357-149">Vhodným způsobem sledování vlastnosti <xref:System.Threading.Tasks.Task.Exception%2A> je použití pokračování, které se spouští pouze v případě selhání předchozího úkolu, jak je znázorněno v následujícím příkladu.</span><span class="sxs-lookup"><span data-stu-id="82357-149">A good way to observe the <xref:System.Threading.Tasks.Task.Exception%2A> property is to use a continuation that runs only if the antecedent task faults, as shown in the following example.</span></span>

[!code-csharp[TPL_Exceptions#27](../../../samples/snippets/csharp/VS_Snippets_Misc/tpl_exceptions/cs/exceptionprop21.cs#27)]
[!code-vb[TPL_Exceptions#27](../../../samples/snippets/visualbasic/VS_Snippets_Misc/tpl_exceptions/vb/exceptionprop21.vb#27)]

<span data-ttu-id="82357-150">V smysluplné aplikaci může delegát pokračování Protokolovat podrobné informace o výjimce a případně vytvořit nové úlohy pro zotavení z výjimky.</span><span class="sxs-lookup"><span data-stu-id="82357-150">In a meaningful application, the continuation delegate could log detailed information about the exception and possibly spawn new tasks to recover from the exception.</span></span> <span data-ttu-id="82357-151">Pokud chyby úlohy, vyvolají následující výrazy výjimku:</span><span class="sxs-lookup"><span data-stu-id="82357-151">If a task faults, the following expressions throw the exception:</span></span>

- `await task`
- `task.Wait()`
- `task.Result`
- `task.GetAwaiter().GetResult()`

<span data-ttu-id="82357-152">Použijte [`try-catch`](../../csharp/language-reference/keywords/try-catch.md) příkaz pro zpracování a sledování vyvolaných výjimek.</span><span class="sxs-lookup"><span data-stu-id="82357-152">Use a [`try-catch`](../../csharp/language-reference/keywords/try-catch.md) statement to handle and observe thrown exceptions.</span></span> <span data-ttu-id="82357-153">Případně můžete pozorovat výjimku přístupem k <xref:System.Threading.Tasks.Task.Exception%2A?displayProperty=nameWithType> Vlastnosti.</span><span class="sxs-lookup"><span data-stu-id="82357-153">Alternatively, observe the exception by accessing the <xref:System.Threading.Tasks.Task.Exception%2A?displayProperty=nameWithType> property.</span></span>

## <a name="unobservedtaskexception-event"></a><span data-ttu-id="82357-154">Událost UnobservedTaskException</span><span class="sxs-lookup"><span data-stu-id="82357-154">UnobservedTaskException event</span></span>

<span data-ttu-id="82357-155">V některých situacích, jako je například hostování nedůvěryhodných zásuvných modulů, mohou být neškodné výjimky běžné a může být příliš obtížné je všechny sledovat ručně.</span><span class="sxs-lookup"><span data-stu-id="82357-155">In some scenarios, such as when hosting untrusted plug-ins, benign exceptions might be common, and it might be too difficult to manually observe them all.</span></span> <span data-ttu-id="82357-156">V těchto případech je možné zpracovat událost <xref:System.Threading.Tasks.TaskScheduler.UnobservedTaskException?displayProperty=nameWithType>.</span><span class="sxs-lookup"><span data-stu-id="82357-156">In these cases, you can handle the <xref:System.Threading.Tasks.TaskScheduler.UnobservedTaskException?displayProperty=nameWithType> event.</span></span> <span data-ttu-id="82357-157">Instance <xref:System.Threading.Tasks.UnobservedTaskExceptionEventArgs?displayProperty=nameWithType>, která je předána obslužné rutině, může být použita k zamezení šíření nesledovaných výjimek zpět do spojovacího vlákna.</span><span class="sxs-lookup"><span data-stu-id="82357-157">The <xref:System.Threading.Tasks.UnobservedTaskExceptionEventArgs?displayProperty=nameWithType> instance that is passed to your handler can be used to prevent the unobserved exception from being propagated back to the joining thread.</span></span>

## <a name="see-also"></a><span data-ttu-id="82357-158">Viz také</span><span class="sxs-lookup"><span data-stu-id="82357-158">See also</span></span>

- [<span data-ttu-id="82357-159">Task Parallel Library (TPL)</span><span class="sxs-lookup"><span data-stu-id="82357-159">Task Parallel Library (TPL)</span></span>](task-parallel-library-tpl.md)
